2021-07-01 17:06:57,596 : Core : INFO     :: None : None : Logging system online
2021-07-01 17:06:57,609 : Core : INFO     :: None : None : Server online
2021-07-01 17:07:19,598 : Core : INFO     :: None : None : Serviced request forhttps://www.github.com/AgentNoon239/unblock-all
2021-07-01 17:07:21,892 : Core : ERROR    :: None : ['  File "C:\\Users\\abc\\Desktop\\Tools\\Python\\unblock-all\\src\\backend.py", line 65, in do_GET\n    file = format_site(url)\n'] : HTTPSConnectionPool(host='users', port=443): Max retries exceeded with url: /AgentNoon239/hovercard?subject=repository%3A371364412&current_path=%2Fwww.github.com%2FAgentNoon239%2Funblock-all (Caused by NewConnectionError('<urllib3.connection.HTTPSConnection object at 0x000001B2C77D58E0>: Failed to establish a new connection: [Errno 11001] getaddrinfo failed'))
2021-07-01 17:07:31,479 : Core : INFO     :: None : None : Serviced request forhttps://stackoverflow.com/questions/1602934/check-if-a-given-key-already-exists-in-a-dictionary
2021-07-01 17:07:34,529 : Core : ERROR    :: None : ['  File "C:\\Users\\abc\\Desktop\\Tools\\Python\\unblock-all\\src\\backend.py", line 65, in do_GET\n    file = format_site(url)\n'] : HTTPSConnectionPool(host='posts', port=443): Max retries exceeded with url: /1602934/ivc/3c2d?_=1625155651571 (Caused by NewConnectionError('<urllib3.connection.HTTPSConnection object at 0x000001B2C77D5760>: Failed to establish a new connection: [Errno 11001] getaddrinfo failed'))
